2016-06-16 20:26:00,267 - pykafka.cluster - ERROR - Unable to connect to broker localhost:9092. Continuing.
2016-06-16 20:26:00,267 - pykafka.cluster - ERROR - [Errno 111] Connection refused
Traceback (most recent call last):
  File "local/lib/python2.7/site-packages/pykafka/cluster.py", line 242, in _request_metadata
    ssl_config=self._ssl_config)
  File "local/lib/python2.7/site-packages/pykafka/broker.py", line 97, in __init__
    self.connect()
  File "local/lib/python2.7/site-packages/pykafka/broker.py", line 211, in connect
    self._connection.connect(self._socket_timeout_ms)
  File "local/lib/python2.7/site-packages/pykafka/connection.py", line 169, in connect
    (self.source_host, self.source_port)
  File "/usr/lib/python2.7/socket.py", line 571, in create_connection
    raise err
error: [Errno 111] Connection refused
2016-06-16 20:26:00,269 - pykafka.cluster - ERROR - Unable to connect to broker localhost:9092. Continuing.
2016-06-16 20:26:00,269 - pykafka.cluster - ERROR - [Errno 111] Connection refused
Traceback (most recent call last):
  File "local/lib/python2.7/site-packages/pykafka/cluster.py", line 242, in _request_metadata
    ssl_config=self._ssl_config)
  File "local/lib/python2.7/site-packages/pykafka/broker.py", line 97, in __init__
    self.connect()
  File "local/lib/python2.7/site-packages/pykafka/broker.py", line 211, in connect
    self._connection.connect(self._socket_timeout_ms)
  File "local/lib/python2.7/site-packages/pykafka/connection.py", line 169, in connect
    (self.source_host, self.source_port)
  File "/usr/lib/python2.7/socket.py", line 571, in create_connection
    raise err
error: [Errno 111] Connection refused
2016-06-16 20:26:00,269 - pykafka.cluster - ERROR - Unable to connect to broker localhost:9092. Continuing.
2016-06-16 20:26:00,270 - pykafka.cluster - ERROR - [Errno 111] Connection refused
Traceback (most recent call last):
  File "local/lib/python2.7/site-packages/pykafka/cluster.py", line 242, in _request_metadata
    ssl_config=self._ssl_config)
  File "local/lib/python2.7/site-packages/pykafka/broker.py", line 97, in __init__
    self.connect()
  File "local/lib/python2.7/site-packages/pykafka/broker.py", line 211, in connect
    self._connection.connect(self._socket_timeout_ms)
  File "local/lib/python2.7/site-packages/pykafka/connection.py", line 169, in connect
    (self.source_host, self.source_port)
  File "/usr/lib/python2.7/socket.py", line 571, in create_connection
    raise err
error: [Errno 111] Connection refused
2016-06-16 20:26:00,269 - pykafka.cluster - ERROR - Unable to connect to broker localhost:9092. Continuing.
2016-06-16 20:26:00,270 - pykafka.cluster - ERROR - [Errno 111] Connection refused
2016-06-16 20:26:00,269 - pykafka.cluster - ERROR - Unable to connect to broker localhost:9092. Continuing.
2016-06-16 20:26:00,270 - pykafka.cluster - ERROR - [Errno 111] Connection refused
